Workbook
Name spotify_data_clean: Data!$A$1:$O$8583

Sheet Data quality
A2: Column name | B2: track_id | C2: track_name | D2: track_number | E2: track_popularity | F2: explicit | G2: artist_name | H2: artist_popularity | I2: artist_followers | J2: artist_genres | K2: album_id | L2: album_name | M2: album_release_date | N2: album_total_tracks | O2: album_type | P2: track_duration_min
A3: % of blank | B3: =COUNTBLANK(Data!A2:A8583)/COUNTA(Data!A2:A8583) -> 0 | C3: =COUNTBLANK(Data!B2:B8583)/COUNTA(Data!B2:B8583) -> 0 | D3: =COUNTBLANK(Data!C2:C8583)/COUNTA(Data!C2:C8583) -> 0 | E3: =COUNTBLANK(Data!D2:D8583)/COUNTA(Data!D2:D8583) -> 0 | F3: =COUNTBLANK(Data!E2:E8583)/COUNTA(Data!E2:E8583) -> 0 | G3: =COUNTBLANK(Data!F2:F8583)/COUNTA(Data!F2:F8583) -> 0 | H3: =COUNTBLANK(Data!G2:G8583)/COUNTA(Data!G2:G8583) -> 0 | I3: =COUNTBLANK(Data!H2:H8583)/COUNTA(Data!H2:H8583) -> 0 | ... P3: =COUNTBLANK(Data!O2:O8583)/COUNTA(Data!O2:O8583) -> 0
A4: % of n/a | B4: =COUNTIF(Data!A2:A8583,"N/A")/COUNTA(Data!A2:A8583) -> 0 | C4: =COUNTIF(Data!B2:B8583,"N/A")/COUNTA(Data!B2:B8583) -> 0 | D4: =COUNTIF(Data!C2:C8583,"N/A")/COUNTA(Data!C2:C8583) -> 0 | E4: =COUNTIF(Data!D2:D8583,"N/A")/COUNTA(Data!D2:D8583) -> 0 | F4: =COUNTIF(Data!E2:E8583,"N/A")/COUNTA(Data!E2:E8583) -> 0 | G4: =COUNTIF(Data!F2:F8583,"N/A")/COUNTA(Data!F2:F8583) -> 0.00034956887 | H4: =COUNTIF(Data!G2:G8583,"N/A")/COUNTA(Data!G2:G8583) -> 0 | I4: =COUNTIF(Data!H2:H8583,"N/A")/COUNTA(Data!H2:H8583) -> 0 | ... P4: =COUNTIF(Data!O2:O8583,"N/A")/COUNTA(Data!O2:O8583) -> 0

Sheet Data
A1: track_id | B1: track_name | C1: track_number | D1: track_popularity | E1: explicit | F1: artist_name | G1: artist_popularity | H1: artist_followers | I1: artist_genres | J1: album_id | K1: album_name | L1: album_release_date | M1: album_total_tracks | N1: album_type | O1: track_duration_min
A2: 3EJS5LyekDim1Tf5rBFmZl | B2: Trippy Mane (ft. Project Pat) | C2: 4 | D2: 0 | E2: TRUE | F2: Diplo | G2: 77 | H2: 2812821 | I2: moombahton | J2: 5QRFnGnBeMGePBKF2xTz5z | K2: d00mscrvll, Vol. 1 | L2: 45961 | M2: 9 | N2: album | O2: 1.55
A3: 1oQW6G2ZiwMuHqlPpP27DB | B3: OMG! | C3: 1 | D3: 0 | E3: TRUE | F3: Yelawolf | G3: 64 | H3: 2363438 | I3: country hip hop, southern hip hop | J3: 4SUmmwnv0xTjRcLdjczGg2 | K3: OMG! | L3: 45961 | M3: 1 | N3: single | O3: 3.07
A4: 7mdkjzoIYlf1rx9EtBpGmU | B4: Hard 2 Find | C4: 1 | D4: 4 | E4: TRUE | F4: Riff Raff | G4: 48 | H4: 193302 | I4: N/A | J4: 3E3zEAL8gUYWaLYB9L7gbp | K4: Hard 2 Find | L4: 45961 | M4: 1 | N4: single | O4: 2.55
A5: 67rW0Zl7oB3qEpD5YWWE5w | B5: Still Get Like That (ft. Project Pat & Starrah) | C5: 8 | D5: 30 | E5: TRUE | F5: Diplo | G5: 77 | H5: 2813710 | I5: moombahton | J5: 5QRFnGnBeMGePBKF2xTz5z | K5: d00mscrvll, Vol. 1 | L5: 45961 | M5: 9 | N5: album | O5: 1.69
A6: 15xptTfRBrjsppW0INUZjf | B6: ride me like a harley | C6: 2 | D6: 0 | E6: TRUE | F6: Rumelis | G6: 48 | H6: 8682 | I6: dark r&b | J6: 06FDIpSHYmZAZoyuYtc7kd | K6: come closer / ride me like a harley | L6: 45960 | M6: 2 | N6: single | O6: 2.39
A7: 4ccpCcZYseq8VrPMK1EDs0 | B7: BLEED | C7: 1 | D7: 2 | E7: FALSE | F7: Minzie | G7: 46 | H7: 7218 | I7: dark r&b | J7: 2NQv9p3ZQW0Ed1LB9enix8 | K7: BLEED | L7: 45960 | M7: 3 | N7: single | O7: 2.76
A8: 3QoQ3HqXTAjgEl9LbNMbYp | B8: Te Procuro na Cidade | C8: 1 | D8: 20 | E8: FALSE | F8: AZERDK | G8: 30 | H8: 1657 | I8: N/A | J8: 1PpuOsLjPWshDLxkr0oHeU | K8: Te Procuro na Cidade | L8: 45960 | M8: 1 | N8: single | O8: 4.12
A9: 1YEZbdT417SfolPQzaoHs2 | B9: come closer | C9: 1 | D9: 27 | E9: FALSE | F9: Rumelis | G9: 49 | H9: 8802 | I9: dark r&b | J9: 06FDIpSHYmZAZoyuYtc7kd | K9: come closer / ride me like a harley | L9: 45960 | M9: 2 | N9: single | O9: 2.53
A10: 4pZ949nFW5SurwzE0TSe7I | B10: Cupido Vagabundo | C10: 1 | D10: 16 | E10: FALSE | F10: Toni dos Anjos | G10: 6 | H10: 475 | I10: N/A | J10: 60DLQZkzpvDvVfvEC6VOJM | K10: Cupido Vagabundo | L10: 45960 | M10: 2 | N10: single | O10: 2.92
A11: 0L0LgwFZ7UtBnRNQvSBty6 | B11: LET‚ÄôS GO! | C11: 1 | D11: 33 | E11: TRUE | F11: PsychoYP | G11: 48 | H11: 154802 | I11: nigerian drill, alt√©, afro adura, afrobeats, afrobeat, afroswing | J11: 3ARxksm8CspGeAaZZB1v2w | K11: LET‚ÄôS GO! | L11: 45958 | M11: 1 | N11: single | O11: 2.4
A12: 5mfAZwEr4jAVDnSY0HHuyH | B12: Stray | C12: 1 | D12: 30 | E12: FALSE | F12: What Matters The Most | G12: 25 | H12: 814 | I12: N/A | J12: 0DHsJaaMzbygWosCjYk37t | K12: Stray | L12: 45955 | M12: 4 | N12: single | O12: 2.49
A13: 4V1Sh9Y2z6e8HpzNOet5rC | B13: PAPARAZZI ARRIVE - English Ver. | C13: 1 | D13: 48 | E13: FALSE | F13: A2O | G13: 46 | H13: 13826 | I13: c-pop | J13: 54XcHEnJ2BKMOzkeRrRubu | K13: PAPARAZZI ARRIVE | L13: 45954 | M13: 14 | N13: album | O13: 2.89
... A37: 1nNgDKWWX9MU9cp5FrHXRN | B37: Love Crazy - Stash Konig Remix | C37: 1 | D37: 31 | E37: FALSE | F37: MisterNez | G37: 18 | H37: 200 | I37: N/A | J37: 2kepsE9qO2QRTLCsF1byjn | K37: Love Crazy (Stash Konig Remix) | L37: 45950 | M37: 1 | N37: single | O37: 3.26
A38: 4ljqKsDyZzicNpBIMvDaZ5 | B38: One More Time | C38: 5 | D38: 6 | E38: FALSE | F38: Fraser Stott | G38: 13 | H38: 119 | I38: N/A | J38: 179fPnGB9pMjUUH2pT02o0 | K38: 19 | L38: 45949 | M38: 9 | N38: album | O38: 3.94
A39: 5hw7dvgBRLvlCiALWwujYz | B39: Nectar - B-Rain Remix | C39: 2 | D39: 29 | E39: FALSE | F39: Senhit | G39: 27 | H39: 54636 | I39: N/A | J39: 4Z53gLriAjTmR7DQr1LRY4 | K39: Nectar (The Remixes) | L39: 45947 | M39: 3 | N39: single | O39: 2.95
A40: 6OTDBDVaK18xlne9rlGQok | B40: No Glory | C40: 1 | D40: 52 | E40: FALSE | F40: Besomorph | G40: 58 | H40: 146944 | I40: slap house | J40: 1jO43qFvbxg7hdp2LgMmyw | K40: No Glory | L40: 45947 | M40: 1 | N40: single | O40: 2.37
A41: 1NXbNEAcPvY5G1xvfN57aA | B41: Dracula | C41: 3 | D41: 80 | E41: TRUE | F41: Tame Impala | G41: 84 | H41: 9509731 | I41: neo-psychedelic, indie | J41: 5WulAOx9ilWy1h8UGZ1gkI | K41: Deadbeat | L41: 45947 | M41: 12 | N41: album | O41: 3.42
A42: 6gRNWnK8b8BVfzrF65HGcf | B42: PSYCHWARD (with WesGhost ft. Project Pat) | C42: 1 | D42: 51 | E42: TRUE | F42: Diplo | G42: 77 | H42: 2812337 | I42: moombahton | J42: 5oq9z5XNldcl7wTiEamVvo | K42: PSYCHWARD | L42: 45947 | M42: 4 | N42: single | O42: 2.88
A43: 1e73KA7YWgIS9cLszZJRTu | B43: Where Have You Been | C43: 1 | D43: 38 | E43: FALSE | F43: Ken | G43: 50 | H43: 7219 | I43: hypertechno | J43: 5OPlNhEIlxUifin4l0gPL6 | K43: Where Have You Been | L43: 45947 | M43: 1 | N43: single | O43: 2.08
A44: 44NbFZ0gEZ4U0LMMsHWyb3 | B44: Great Tomorrow | C44: 1 | D44: 3 | E44: FALSE | F44: Kxng Le√≥ | G44: 1 | H44: 177 | I44: N/A | J44: 0jFDIZgcya0j2cfR17izT9 | K44: Great Tomorrow | L44: 45947 | M44: 1 | N44: single | O44: 2.21
A45: 05RK4klU7S2Jm50ONIjyM4 | B45: Hearts Grow Cold (Saint No√´l) [feat. Olivia Cadenza] | C45: 1 | D45: 50 | E45: FALSE | F45: Kayote | G45: 49 | H45: 19306 | I45: N/A | J45: 0Kil1i9WrmbacxToZg8qk9 | K45: Hearts Grow Cold (Saint No√™l) [feat. Olivia Cadenza] | L45: 45947 | M45: 1 | N45: single | O45: 2.65
A46: 0Oriikd4ETp5qmzek6ZUD5 | B46: Talk To You (ft. Elton John) | C46: 1 | D46: 72 | E46: TRUE | F46: Sam Fender | G46: 73 | H46: 1204977 | I46: N/A | J46: 5tmaU5xBUYQYr2VkWhokIb | K46: Talk To You (ft. Elton John) | L46: 45947 | M46: 1 | N46: single | O46: 5.28
A47: 5jw5yNpSTxdBAr1AV3N96s | B47: The Way I Am Now | C47: 1 | D47: 25 | E47: FALSE | F47: Lila Holler | G47: 17 | H47: 1068 | I47: N/A | J47: 7xpJHorbY32dNwaRlBgXC5 | K47: The Way I Am Now | L47: 45947 | M47: 1 | N47: single | O47: 3.77
A48: 0lRnxwJeUOxwEvWMw4uQKj | B48: Think About Us | C48: 1 | D48: 68 | E48: FALSE | F48: Sonny Fodera | G48: 66 | H48: 306842 | I48: house | J48: 1jmVSpWhzD8vciWg2Qtd5V | K48: Think About Us | L48: 45947 | M48: 1 | N48: single | O48: 2.96
A49: 6q43CVVE0VXEWlDjPdgH0c | B49: Trophy Wife | C49: 1 | D49: 32 | E49: TRUE | F49: Annalise Azadian | G49: 31 | H49: 5701 | I49: N/A | J49: 5XWqunjy0GiCQIOLtEyuyr | K49: Trophy Wife | L49: 45947 | M49: 1 | N49: single | O49: 2.86
A50: 0vXBmU9Zus9ZtbR4kvZAjH | B50: baby can you sin for me | C50: 1 | D50: 52 | E50: FALSE | F50: Ex Habit | G50: 59 | H50: 130408 | I50: dark r&b | J50: 5eudqcLVRKtOtQdlHQ2yrm | K50: baby can you sin for me | L50: 45946 | M50: 1 | N50: single | O50: 2.69
... A407: 5H1sKFMzDeMtXwND3V6hRY | B407: JUMP | C407: 1 | D407: 90 | E407: FALSE | F407: BLACKPINK | G407: 81 | H407: 56152334 | I407: k-pop | J407: 3hzoZlx2KwtvJEUl9piPWr | K407: JUMP | L407: 45849 | M407: 1 | N407: single | O407: 2.74
A408: 7gCautqfD7CCdrN33GrRd8 | B408: 405 | C408: 17 | D408: 63 | E408: FALSE | F408: Justin Bieber | G408: 91 | H408: 85008100 | I408: pop, contemporary r&b | J408: 5vD5M5VW62LL78Ko8x0CVZ | K408: SWAG | L408: 45849 | M408: 21 | N408: album | O408: 3.54
A409: 72PVbRKkUimweUPV0nKAPs | B409: ALL I CAN TAKE | C409: 1 | D409: 71 | E409: FALSE | F409: Justin Bieber | G409: 91 | H409: 85050158 | I409: pop, contemporary r&b | J409: 5vD5M5VW62LL78Ko8x0CVZ | K409: SWAG | L409: 45849 | M409: 21 | N409: album | O409: 4.12
A410: 0lUXjVdwD90F7coLj0aabz | B410: Alright | C410: 1 | D410: 45 | E410: FALSE | F410: Scoobert Doobert | G410: 36 | H410: 5521 | I410: N/A | J410: 1wvfvKidzPjbiGFBEb0n5T | K410: Alright | L410: 45849 | M410: 1 | N410: single | O410: 3.36
A411: 5cfsQZEFf1IpQr8F9vI9le | B411: BUTTERFLIES | C411: 6 | D411: 67 | E411: FALSE | F411: Justin Bieber | G411: 91 | H411: 85008100 | I411: pop, contemporary r&b | J411: 5vD5M5VW62LL78Ko8x0CVZ | K411: SWAG | L411: 45849 | M411: 21 | N411: album | O411: 3.22
A412: 1MVT5RV5LTO4FQ4bUKjvRr | B412: no one ever warns you | C412: 1 | D412: 32 | E412: FALSE | F412: Olivia Soli | G412: 15 | H412: 2381 | I412: N/A | J412: 6IMrYT25DPqimzpTOjtbwm | K412: no one ever warns you | L412: 45849 | M412: 1 | N412: single | O412: 3.25
A413: 5WqA7iqtEMmnN9nkdTSW2p | B413: Out Of The Dark | C413: 1 | D413: 52 | E413: FALSE | F413: LMNT 115 | G413: 35 | H413: 5813 | I413: N/A | J413: 1iTQQDXtrER9NQZMPGqKfZ | K413: Out Of The Dark | L413: 45849 | M413: 1 | N413: single | O413: 2.53
A414: 3WQ5w7ruC3c861lHXF9Gs2 | B414: SWAG | C414: 18 | D414: 65 | E414: TRUE | F414: Justin Bieber | G414: 91 | H414: 85008100 | I414: pop, contemporary r&b | J414: 5vD5M5VW62LL78Ko8x0CVZ | K414: SWAG | L414: 45849 | M414: 21 | N414: album | O414: 2.5
A415: 6AX3i1TluzbvpJpKrY7NoD | B415: SWEET SPOT | C415: 15 | D415: 66 | E415: TRUE | F415: Justin Bieber | G415: 91 | H415: 85022258 | I415: pop, contemporary r&b | J415: 5vD5M5VW62LL78Ko8x0CVZ | K415: SWAG | L415: 45849 | M415: 21 | N415: album | O415: 3.08
A416: 7tZlvvEpX3FEFoYsOI55FB | B416: THERAPY SESSION | C416: 14 | D416: 58 | E416: TRUE | F416: Justin Bieber | G416: 91 | H416: 85022258 | I416: pop, contemporary r&b | J416: 5vD5M5VW62LL78Ko8x0CVZ | K416: SWAG | L416: 45849 | M416: 21 | N416: album | O416: 1.31
A417: 1j8TmNa6vaFAEAws43kP0Q | B417: THINGS YOU DO | C417: 5 | D417: 70 | E417: FALSE | F417: Justin Bieber | G417: 91 | H417: 85022258 | I417: pop, contemporary r&b | J417: 5vD5M5VW62LL78Ko8x0CVZ | K417: SWAG | L417: 45849 | M417: 21 | N417: album | O417: 1.8
A418: 422PeUrBywndaCCxL6bDBj | B418: TOO LONG | C418: 20 | D418: 65 | E418: TRUE | F418: Justin Bieber | G418: 91 | H418: 85008100 | I418: pop, contemporary r&b | J418: 5vD5M5VW62LL78Ko8x0CVZ | K418: SWAG | L418: 45849 | M418: 21 | N418: album | O418: 3.07
A419: 6Ql76QUTIXajTh9cVjrAZl | B419: Vodka Cranberry | C419: 1 | D419: 72 | E419: FALSE | F419: Conan Gray | G419: 79 | H419: 12428221 | I419: N/A | J419: 0Z5FaBjNQ1sZ2Udunf17Jt | K419: Vodka Cranberry | L419: 45849 | M419: 2 | N419: single | O419: 4.09
...

Sheet genres
A1: artist_name | B1: artist_followers | C1: artist_genres
A2: Diplo | B2: 2812821 | C2: moombahton | N2: Row Labels | O2: Count of artist_name
A3: Yelawolf | B3: 2363438 | C3: country hip hop | D3: southern hip hop | N3: alternative pop | O3: 160
A4: Riff Raff | B4: 193302 | C4: N/A | N4: art pop | O4: 115
A5: Diplo | B5: 2813710 | C5: moombahton | N5: country | O5: 572
A6: Rumelis | B6: 8682 | C6: dark r&b | N6: dark r&b | O6: 118
A7: Minzie | B7: 7218 | C7: dark r&b | N7: pop | O7: 516
A8: AZERDK | B8: 1657 | C8: N/A | N8: pop rock | O8: 100
A9: Rumelis | B9: 8802 | C9: dark r&b | N9: r&b pop | O9: 141
A10: Toni dos Anjos | B10: 475 | C10: N/A | N10: rap | O10: 268
A11: PsychoYP | B11: 154802 | C11: nigerian drill | D11: alt√© | E11: afro adura | F11: afrobeats | G11: afrobeat | H11: afroswing | N11: soft pop | O11: 213
A12: What Matters The Most | B12: 814 | C12: N/A | N12: soundtrack | O12: 352
A13: A2O | B13: 13826 | C13: c-pop | N13: Grand Total | O13: 2555
A14: Daniel Caesar | B14: 11137714 | C14: N/A
A15: Ovi Jozi | B15: 3567 | C15: N/A
A16: A2O | B16: 13590 | C16: c-pop
A17: Leon Thomas | B17: 735818 | C17: N/A
A18: Joe Hermes | B18: 1518 | C18: N/A
A19: A2O | B19: 13826 | C19: c-pop
A20: Scarlett Butler | B20: 364 | C20: N/A
A21: LEROCQUE | B21: 13770 | C21: N/A
A22: Xander Ward | B22: 729 | C22: N/A
A23: The All-American Rejects | B23: 3134186 | C23: pop punk | D23: emo
A24: Smith & Liddle | B24: 543 | C24: N/A
A25: Artemas | B25: 1378935 | C25: N/A
A26: YUNG ALPO | B26: 166 | C26: N/A
A27: A2O | B27: 13826 | C27: c-pop
A28: PRAX | B28: 1982 | C28: N/A
A29: Mark II | B29: 722 | C29: N/A
A30: Suark | B30: 1496 | C30: N/A
A31: Vince Bello | B31: 84 | C31: N/A
A32: Anna Marx | B32: 1693 | C32: N/A
A33: Ana Shine | B33: 27570 | C33: N/A
A34: Stray Currents | B34: 1073 | C34: N/A
A35: Sopperior | B35: 2891 | C35: N/A
... A40: Besomorph | B40: 146944 | C40: slap house
A41: Tame Impala | B41: 9509731 | C41: neo-psychedelic | D41: indie
A42: Diplo | B42: 2812337 | C42: moombahton
A43: Ken | B43: 7219 | C43: hypertechno
A44: Kxng Le√≥ | B44: 177 | C44: N/A
...

Sheet Charts
AI6: Row Labels | AJ6: Average of artist_followers
AI7: Taylor Swift | AJ7: 1.4543996e+08
AI8: Ed Sheeran | AJ8: 1.2278474e+08
AI9: Billie Eilish | AJ9: 1.1871188e+08
AI10: The Weeknd | AJ10: 1.1295567e+08
AI11: Ariana Grande | AJ11: 1.073897e+08
AI12: Eminem | AJ12: 1.0453655e+08
AI13: Drake | AJ13: 1.0306154e+08
AI14: Bad Bunny | AJ14: 1.0253335e+08
AI15: Justin Bieber | AJ15: 85020552
AI16: BTS | AJ16: 81187032
AI17: Grand Total | AJ17: 1.1959344e+08
J18: Years (album_release_date) | K18: (Multiple Items)
K20: Column Labels
K21: Taylor Swift | L21: The Weeknd | M21: Post Malone | N21: Ariana Grande | O21: Drake | P21: Olivia Rodrigo | Q21: Billie Eilish | R21: Lil Peep | S21: Bad Bunny | T21: Tate McRae
J22: Count of track_id | K22: 250 | L22: 106 | M22: 83 | N22: 82 | O22: 73 | P22: 68 | Q22: 61 | R22: 60 | S22: 56 | T22: 48
AF35: Row Labels | AG35: Count of track_id
AF36: 2015 | AG36: 383
AF37: 2016 | AG37: 376
AF38: 2017 | AG38: 458
AF39: 2018 | AG39: 522
AF40: 2019 | AG40: 496
AF41: 2020 | AG41: 480
AF42: 2021 | AG42: 443
AF43: 2022 | AG43: 468
AF44: 2023 | AG44: 523
AF45: 2024 | AG45: 648
AF46: 2025 | AG46: 765
AF47: Grand Total | AG47: 5562
J48: Row Labels | K48: Average of artist_popularity | L48: Count of track_id | P48: correl | R48: Row Labels | S48: Count of track_id | T48: Average of artist_followers | X48: correl
J49: $uicideboy$ | K49: 83 | L49: 2 | M49: 83 | N49: 2 | P49: =CORREL(M49:M155,N49:N155) -> 0.65883552 | R49: Taylor Swift | S49: 324 | T49: 1.4543996e+08 | X49: =CORREL(U50:U155,V50:V155) -> 0.63426329
J50: 21 Savage | K50: 84 | L50: 7 | M50: 84 | N50: 7 | R50: Ed Sheeran | S50: 53 | T50: 1.2278474e+08 | U50: 53 | V50: 1.2278474e+08
J51: 50 Cent | K51: 82 | L51: 6 | M51: 82 | N51: 6 | R51: Billie Eilish | S51: 61 | T51: 1.1871188e+08 | U51: 61 | V51: 1.1871188e+08
J52: A$AP Rocky | K52: 82 | L52: 7 | M52: 82 | N52: 7 | R52: The Weeknd | S52: 141 | T52: 1.1295567e+08 | U52: 141 | V52: 1.1295567e+08
J53: Adele | K53: 83 | L53: 41 | M53: 83 | N53: 41 | R53: Ariana Grande | S53: 94 | T53: 1.073897e+08 | U53: 94 | V53: 1.073897e+08
J54: Alex Warren | K54: 84 | L54: 5 | M54: 84 | N54: 5 | R54: Eminem | S54: 67 | T54: 1.0453655e+08 | U54: 67 | V54: 1.0453655e+08
J55: Arc√°ngel | K55: 82 | L55: 1 | M55: 82 | N55: 1 | R55: Drake | S55: 84 | T55: 1.0306154e+08 | U55: 84 | V55: 1.0306154e+08
J56: Arctic Monkeys | K56: 84 | L56: 10 | M56: 84 | N56: 10 | R56: Bad Bunny | S56: 56 | T56: 1.0253335e+08 | U56: 56 | V56: 1.0253335e+08
J57: Ariana Grande | K57: 90 | L57: 94 | M57: 90 | N57: 94 | R57: Justin Bieber | S57: 55 | T57: 85020552 | U57: 55 | V57: 85020552
J58: Bad Bunny | K58: 95 | L58: 56 | M58: 95 | N58: 56 | R58: BTS | S58: 30 | T58: 81187032 | U58: 30 | V58: 81187032
...

Sheet Dashboard
